Workbook
Name _Hlk161219787: 'Nota 3'!$B$34
Name _Hlk161831706: 'Nota 3'!$B$58
Name _Hlk161832494: 'Nota 5 Txt'!$B$224
Name _Hlk161986056: 'Dictamen 1'!$B$23
Name _Hlk161986056: 'Dictamen 2'!#REF!
Name _Hlk161987517: 'Nota 3'!$B$33
Name _Hlk161988619: 'Nota 3'!$B$57
Name _TOC_250001: Datos!#REF!
Name _TOC_250001: CF!$B$10
Name OLE_LINK1: Datos!#REF!
Name OLE_LINK1: BG!$B$12

Sheet Datos
B2: Datos del documento
B4: Nombre Linea 1: | C4: Fideicomiso Irrevocable 4341
B5: Nombre Linea 2: | C5: Fideicomiso FORTMCK 19-12 Lomas Verdes
B6: Fecha del Balance: | C6: Al 31 de diciembre de 2024 y 2023
B7: Fecha del Estado de resultdos: | C7: Por los ejercicios terminados al 31 de diciembre de 2024 y 2023
B8: Año actual: | C8: 2024
B9: Año anterior: | C9: 2023
B10: Fecha del dictamen: | C10: 30 de abril de 2025
B11: =+CONCATENATE("Resultado de ",C9-1) -> Resultado de 2022 | C11: -292
C12: Fideicomiso por el año que terminó el 31 de diciembre de 2023
C13: estados financieros el 28 de abril de 2023
C14: Al 31 de diciembre de 2024 y 2023
C15: Los saldos por pagar al 31 de diciembre de 2024 y 2023
C16: El 27 de diciembre de 2022
C17: 1o de enero de 2024
C18: Al 31 de diciembre de 2024 y 2023
C19: El Fideicomiso al 31 de diciembre de 2024
C20: 1o de enero de 2023

Sheet Catálogo
A1: Cuenta | B1: Scta | C1: SSCta | D1: Descripción | F1: Rubro | G1: Nota
A2: 103 | B2: 0 | C2: 0 | D2: BANCOS | E2: 1030BANCOS | F2: #N/A
A3: 103 | B3: 1 | C3: 0 | D3: MONEDA NACIONAL | E3: 1031MONEDA NACIONAL | F3: #N/A
A4: 103 | B4: 1 | C4: 2 | D4: BBVA CTA 0116008208 | E4: 1031BBVA CTA 0116008208 | F4: Efectivo y equivalentes de efectivo | G4: Depósitos en cuenta de cheques
A5: 103 | B5: 1 | C5: 5 | D5: INVEX CTA 05661 COBRANZA | E5: 1031INVEX CTA 05661 COBRANZA | F5: Efectivo y equivalentes de efectivo | G5: Depósitos en cuenta de cheques
A6: 103 | B6: 1 | C6: 6 | D6: INVEX CTA 05662 RESERVA | E6: 1031INVEX CTA 05662 RESERVA | F6: Efectivo y equivalentes de efectivo | G6: Depósitos en cuenta de cheques
A7: 104 | B7: 0 | C7: 0 | D7: INVERSIONES SISTEMA FINANCIERO | E7: 1040INVERSIONES SISTEMA FINANCIERO | F7: #N/A
A8: 104 | B8: 1 | C8: 0 | D8: MONEDA NACIONAL | E8: 1041MONEDA NACIONAL | F8: #N/A
A9: 104 | B9: 1 | C9: 1 | D9: ACTINVER 8344681 CUENTA GENERAL | E9: 1041ACTINVER 8344681 CUENTA GENERAL | F9: Efectivo y equivalentes de efectivo | G9: =+'N4 Efectivo'!$E$11 -> Inversiones en valores realizables
A10: 104 | B10: 1 | C10: 2 | D10: ACTINVER 8344681 COMPLEMENTARIA | E10: 1041ACTINVER 8344681 COMPLEMENTARIA | F10: Efectivo y equivalentes de efectivo | G10: =+'N4 Efectivo'!$E$11 -> Inversiones en valores realizables
A11: 104 | B11: 1 | C11: 3 | D11: ACTINVER 5371322 CUENTA GENERAL | E11: 1041ACTINVER 5371322 CUENTA GENERAL | F11: Efectivo y equivalentes de efectivo | G11: =+'N4 Efectivo'!$E$11 -> Inversiones en valores realizables
A12: 104 | B12: 1 | C12: 4 | D12: ACTINVER CTA 5371322 COMPLEMENTARIA | E12: 1041ACTINVER CTA 5371322 COMPLEMENTARIA | F12: Efectivo y equivalentes de efectivo | G12: =+'N4 Efectivo'!$E$11 -> Inversiones en valores realizables
A13: 104 | B13: 1 | C13: 5 | D13: INVEX CTA 0705 COBRA INVER | E13: 1041INVEX CTA 0705 COBRA INVER | F13: Efectivo y equivalentes de efectivo | G13: =+'N4 Efectivo'!$E$11 -> Inversiones en valores realizables
A14: 104 | B14: 1 | C14: 6 | D14: INVEX CTA 0705 COBRA INVER COMPLEMENTARI | E14: 1041INVEX CTA 0705 COBRA INVER COMPLEMENTARI | F14: Efectivo y equivalentes de efectivo | G14: =+'N4 Efectivo'!$E$11 -> Inversiones en valores realizables
A15: 104 | B15: 1 | C15: 7 | D15: INVEX CTA 0732 RESERVA INVER | E15: 1041INVEX CTA 0732 RESERVA INVER | F15: Efectivo y equivalentes de efectivo | G15: =+'N4 Efectivo'!$E$11 -> Inversiones en valores realizables
A16: 104 | B16: 1 | C16: 8 | D16: INVEX CTA 0732 RESERVA INVER COMPLEMENTA | E16: 1041INVEX CTA 0732 RESERVA INVER COMPLEMENTA | F16: Efectivo y equivalentes de efectivo | G16: =+'N4 Efectivo'!$E$11 -> Inversiones en valores realizables
A17: 108 | B17: 0 | C17: 0 | D17: CLIENTES | E17: 1080CLIENTES | F17: #N/A
A18: 108 | B18: 1 | C18: 0 | D18: CLIENTES M.N. | E18: 1081CLIENTES M.N. | F18: #N/A
A19: 109 | B19: 0 | C19: 0 | D19: DEUDORES DIVERSOS | E19: 1090DEUDORES DIVERSOS | F19: #N/A
A20: 109 | B20: 1 | C20: 0 | D20: DEUDORES DIVERSOS M.N. | E20: 1091DEUDORES DIVERSOS M.N. | F20: Deudores diversos y otras cuentas por cobrar
A21: 113 | B21: 0 | C21: 0 | D21: ANTICIPO DE IMPUESTOS | E21: 1130ANTICIPO DE IMPUESTOS | F21: #N/A
A22: 113 | B22: 1 | C22: 0 | D22: ISR | E22: 1131ISR | F22: #N/A
A23: 113 | B23: 1 | C23: 1 | D23: ISR PAGO PROVISIONALES | E23: 1131ISR PAGO PROVISIONALES | F23: Impuestos por recuperar | G23: ISR Retenido
A24: 113 | B24: 1 | C24: 2 | D24: ISR RETENCIONES BANCOS | E24: 1131ISR RETENCIONES BANCOS | F24: Impuestos por recuperar | G24: ISR Retenido
A25: 114 | B25: 0 | C25: 0 | D25: IMPUESTOS A FAVOR | E25: 1140IMPUESTOS A FAVOR | F25: #N/A
A26: 114 | B26: 1 | C26: 0 | D26: IVA SALDO A FAVOR | E26: 1141IVA SALDO A FAVOR | F26: #N/A
A27: 114 | B27: 1 | C27: 1 | D27: IVA SALDO A FAVOR AL 16% | E27: 1141IVA SALDO A FAVOR AL 16% | F27: Inventarios inmobiliarios y costos pagados por anticipado | G27: Impuesto al Valor Agregado
A28: 115 | B28: 0 | C28: 0 | D28: IMPUESTOS A FAVOR NO CAUSADO | E28: 1150IMPUESTOS A FAVOR NO CAUSADO | F28: #N/A
A29: 115 | B29: 1 | C29: 0 | D29: IVA ACREDITABLE NO PAGADO | E29: 1151IVA ACREDITABLE NO PAGADO | F29: #N/A
A30: 115 | B30: 1 | C30: 1 | D30: IVA ACREDITABLE NO PAGADO AL 16% | E30: 1151IVA ACREDITABLE NO PAGADO AL 16% | F30: Deudores diversos y otras cuentas por cobrar
E31: 1180PAGOS ANTICIPADOS
E32: 1182PROVEEDORES
E33: 1182BANCO ACTINVER | F33: Inventarios inmobiliarios y costos pagados por anticipado | G33: =+'N5 Inventarios Inm(Tablas)'!$B$16 -> Otros pagos anticipados (v)
A34: 120 | B34: 0 | C34: 0 | D34: ANTICIPOS CONSTRUCCION | E34: 1200ANTICIPOS CONSTRUCCION | F34: #N/A
A35: 120 | B35: 1 | C35: 0 | D35: ANTICIPOS CONSTRUCCION M.N. | E35: 1201ANTICIPOS CONSTRUCCION M.N. | F35: Inventarios inmobiliarios y costos pagados por anticipado | G35: =+'N5 Inventarios Inm(Tablas)'!$B$16 -> Otros pagos anticipados (v)
A36: 121 | B36: 0 | C36: 0 | D36: TERRENOS | E36: 1210TERRENOS | F36: #N/A
A37: 121 | B37: 1 | C37: 0 | D37: INVERSIÓN | E37: 1211INVERSIÓN | F37: #N/A
A38: 121 | B38: 1 | C38: 1 | D38: TERRENO LOTE 18 0980616001000000 | E38: 1211TERRENO LOTE 18 0980616001000000 | F38: Inventarios inmobiliarios y costos pagados por anticipado | G38: =+'N5 Inventarios Inm(Tablas)'!$B$5 -> Terrenos (i)
A39: 121 | B39: 1 | C39: 2 | D39: TERRENO L-19 No, CAT. 0980616002000000 | E39: 1211TERRENO L-19 No, CAT. 0980616002000000 | F39: Inventarios inmobiliarios y costos pagados por anticipado | G39: =+'N5 Inventarios Inm(Tablas)'!$B$5 -> Terrenos (i)
A40: 121 | B40: 1 | C40: 3 | D40: TERRENO L-20 CLAVE No. 0980616003000000 | E40: 1211TERRENO L-20 CLAVE No. 0980616003000000 | F40: Inventarios inmobiliarios y costos pagados por anticipado | G40: =+'N5 Inventarios Inm(Tablas)'!$B$5 -> Terrenos (i)
...

Sheet BalanzaActual
A1: FIDEICOMISO FORTMCK19-12 LOMAS VERDES | S1: FIDEICOMISO FORTMCK19-12 LOMAS VERDES | AH1: Rubro | AI1: Nota
A2: R.F.C.: FFL191202GZ1 Dirección: Av. Santa Fe 505 Int. 802 Piso 8 Col. Cruz Manca CP05349 | S2: R.F.C.: FFL191202GZ1 Dirección: Av. Santa Fe 505 Int. 802 Piso 8 Col. Cruz Manca CP05349 | AG2: =+CONCATENATE(S2,T2,V2) -> R.F.C.: FFL191202GZ1 Dirección: Av. Santa Fe 505 Int. 802 Piso 8 Col. Cruz Manca CP05349 | AH2: =+VLOOKUP(AG2,Catálogo!E:F,2,0) -> #N/A | AI2: =+VLOOKUP(AG2,Catálogo!E:G,3,0) -> #N/A
A3: Periodo de : Enero 2024 a Diciembre 2024 | S3: Periodo de : Enero 2024 a Septiembre 2024 | AG3: =+CONCATENATE(S3,T3,V3) -> Periodo de : Enero 2024 a Septiembre 2024 | AH3: =+VLOOKUP(AG3,Catálogo!E:F,2,0) -> #N/A | AI3: =+VLOOKUP(AG3,Catálogo!E:G,3,0) -> #N/A
A4: Balanza de Comprobación | S4: Balanza de Comprobación | AG4: =+CONCATENATE(S4,T4,V4) -> Balanza de Comprobación | AH4: =+VLOOKUP(AG4,Catálogo!E:F,2,0) -> #N/A | AI4: =+VLOOKUP(AG4,Catálogo!E:G,3,0) -> #N/A
A5: Balanza compartida por el contador: | D5: Andrés Martínez | S5: Balanza compartida por el contador: | V5: Andrés Martínez | AG5: =+CONCATENATE(S5,T5,V5) -> Balanza compartida por el contador:Andrés Martínez | AH5: =+VLOOKUP(AG5,Catálogo!E:F,2,0) -> #N/A | AI5: =+VLOOKUP(AG5,Catálogo!E:G,3,0) -> #N/A
A6: Correo: | B6: amartinez@fortemcapital.com.mx | S6: Correo: | T6: amartinez@fortemcapital.com.mx | AG6: =+CONCATENATE(S6,T6,V6) -> Correo:amartinez@fortemcapital.com.mx | AH6: =+VLOOKUP(AG6,Catálogo!E:F,2,0) -> #N/A | AI6: =+VLOOKUP(AG6,Catálogo!E:G,3,0) -> #N/A
A7: Fecha de envio: 07/03/25 | O7: =+SUM(O11:O152) -> 0 | S7: Fecha de envio: 16/10/2024 | AG7: =+CONCATENATE(S7,T7,V7) -> Fecha de envio: 16/10/2024 | AH7: =+VLOOKUP(AG7,Catálogo!E:F,2,0) -> #N/A | AI7: =+VLOOKUP(AG7,Catálogo!E:G,3,0) -> #N/A
A8: Fecha de descarga: 07/03/25 | S8: Fecha de descarga: 16/10/2024 | AG8: =+CONCATENATE(S8,T8,V8) -> Fecha de descarga: 16/10/2024 | AH8: =+VLOOKUP(AG8,Catálogo!E:F,2,0) -> #N/A | AI8: =+VLOOKUP(AG8,Catálogo!E:G,3,0) -> #N/A
AG9: =+CONCATENATE(S9,T9,V9) | AH9: =+VLOOKUP(AG9,Catálogo!E:F,2,0) -> #N/A | AI9: =+VLOOKUP(AG9,Catálogo!E:G,3,0) -> #N/A
A10: Cuenta | B10: Scta | C10: SSCta | D10: Descripción | E10: Saldo Inicial | F10: Cargos | G10: Abonos | H10: Saldo Actual | K10: Quitar duplicados y cuentas de mayor | N10: Determinar saldos ajustados listos para trabajar | S10: Cuenta | T10: Scta | U10: SSCta | V10: Descripción | W10: Saldo Inicial | X10: Cargos | Y10: Abonos | Z10: Saldo Actual | AG10: =+CONCATENATE(S10,T10,V10) -> CuentaSctaDescripción | AH10: =+VLOOKUP(AG10,Catálogo!E:F,2,0) -> #N/A | AI10: =+VLOOKUP(AG10,Catálogo!E:G,3,0) -> #N/A
A11: 103 | B11: 0 | C11: 0 | D11: BANCOS | E11: 360054.31 | F11: 61942189 | G11: -61837756 | H11: 464487.14 | J11: =+ROUND(H11/1000,0) -> 464 | K11: =+IFERROR(LEFT(AH11,3),0) -> 0 | L11: =+IFERROR(ABS(K11),"ok") -> 0 | M11: =+IF(L11="ok",J11,0) -> 0 | O11: =+M11+N11 -> 0 | S11: 103 | T11: 0 | U11: 0 | V11: BANCOS | W11: 360054.31 | X11: 61942189 | Y11: -61837756 | Z11: =+O11 -> 0 | AG11: =+CONCATENATE(S11,T11,V11) -> 1030BANCOS | AH11: =+VLOOKUP(AG11,Catálogo!E:F,2,0) -> #N/A | AI11: =+VLOOKUP(AG11,Catálogo!E:G,3,0) -> 0
A12: 103 | B12: 1 | C12: 0 | D12: MONEDA NACIONAL | E12: 360054.31 | F12: 61942189 | G12: -61837756 | H12: 464487.14 | J12: =+ROUND(H12/1000,0) -> 464 | K12: =+IFERROR(LEFT(AH12,3),0) -> 0 | L12: =+IFERROR(ABS(K12),"ok") -> 0 | M12: =+IF(L12="ok",J12,0) -> 0 | O12: =+M12+N12 -> 0 | S12: 103 | T12: 1 | U12: 0 | V12: MONEDA NACIONAL | W12: 360054.31 | X12: 61942189 | Y12: -61837756 | Z12: =+O12 -> 0 | AG12: =+CONCATENATE(S12,T12,V12) -> 1031MONEDA NACIONAL | AH12: =+VLOOKUP(AG12,Catálogo!E:F,2,0) -> #N/A | AI12: =+VLOOKUP(AG12,Catálogo!E:G,3,0) -> 0
A13: 103 | B13: 1 | C13: 2 | D13: BBVA CTA 0116008208 | E13: 2749.92 | F13: 26742159 | G13: -26711748 | H13: 33160.16 | J13: =+ROUND(H13/1000,0) -> 33 | K13: =+IFERROR(LEFT(AH13,3),0) -> Efe | L13: =+IFERROR(ABS(K13),"ok") -> ok | M13: =+IF(L13="ok",J13,0) -> 33 | O13: =+M13+N13 -> 33 | S13: 103 | T13: 1 | U13: 2 | V13: BBVA CTA 0116008208 | W13: 2749.92 | X13: 26742159 | Y13: -26711748 | Z13: =+O13 -> 33 | AG13: =+CONCATENATE(S13,T13,V13) -> 1031BBVA CTA 0116008208 | AH13: =+VLOOKUP(AG13,Catálogo!E:F,2,0) -> Efectivo y equivalentes de efectivo | AI13: =+VLOOKUP(AG13,Catálogo!E:G,3,0) -> Depósitos en cuenta de cheques
A14: 103 | B14: 1 | C14: 3 | D14: BBVA CTA 0122389452 | E14: 7291.8 | F14: 0 | G14: -965.12 | H14: 6326.68 | J14: =+ROUND(H14/1000,0) -> 6 | K14: =+IFERROR(LEFT(AH14,3),0) -> Efe | L14: =+IFERROR(ABS(K14),"ok") -> ok | M14: =+IF(L14="ok",J14,0) -> 6 | O14: =+M14+N14 -> 6 | S14: 103 | T14: 1 | U14: 3 | V14: BBVA CTA 0122389452 | W14: 7291.8 | X14: 0 | Y14: -965.12 | Z14: =+O14 -> 6 | AG14: =+CONCATENATE(S14,T14,V14) -> 1031BBVA CTA 0122389452 | AH14: =+VLOOKUP(AG14,Catálogo!E:F,2,0) -> Efectivo y equivalentes de efectivo | AI14: =+VLOOKUP(AG14,Catálogo!E:G,3,0) -> Depósitos en cuenta de cheques
A15: 103 | B15: 1 | C15: 5 | D15: INVEX CTA 05661 COBRANZA | E15: 350012.59 | F15: 35200030 | G15: -35125042 | H15: 425000.3 | J15: =+ROUND(H15/1000,0) -> 425 | K15: =+IFERROR(LEFT(AH15,3),0) -> Efe | L15: =+IFERROR(ABS(K15),"ok") -> ok | M15: =+IF(L15="ok",J15,0) -> 425 | O15: =+M15+N15 -> 425 | S15: 103 | T15: 1 | U15: 5 | V15: INVEX CTA 05661 COBRANZA | W15: 350012.59 | X15: 35200030 | Y15: -35125042 | Z15: =+O15 -> 425 | AG15: =+CONCATENATE(S15,T15,V15) -> 1031INVEX CTA 05661 COBRANZA | AH15: =+VLOOKUP(AG15,Catálogo!E:F,2,0) -> Efectivo y equivalentes de efectivo | AI15: =+VLOOKUP(AG15,Catálogo!E:G,3,0) -> Depósitos en cuenta de cheques
A16: 104 | B16: 0 | C16: 0 | D16: INVERSIONES SISTEMA FINANCIERO | E16: 50825584 | F16: 6.607306e+08 | G16: -6.6930136e+08 | H16: 42254825 | J16: =+ROUND(H16/1000,0) -> 42255 | K16: =+IFERROR(LEFT(AH16,3),0) -> 0 | L16: =+IFERROR(ABS(K16),"ok") -> 0 | M16: =+IF(L16="ok",J16,0) -> 0 | O16: =+M16+N16 -> 0 | S16: 104 | T16: 0 | U16: 0 | V16: INVERSIONES SISTEMA FINANCIERO | W16: 50825584 | X16: 6.607306e+08 | Y16: -6.6930136e+08 | Z16: =+O16 -> 0 | AG16: =+CONCATENATE(S16,T16,V16) -> 1040INVERSIONES SISTEMA FINANCIERO | AH16: =+VLOOKUP(AG16,Catálogo!E:F,2,0) -> #N/A | AI16: =+VLOOKUP(AG16,Catálogo!E:G,3,0) -> 0
A17: 104 | B17: 1 | C17: 0 | D17: MONEDA NACIONAL | E17: 50825584 | F17: 6.607306e+08 | G17: -6.6930136e+08 | H17: 42254825 | J17: =+ROUND(H17/1000,0) -> 42255 | K17: =+IFERROR(LEFT(AH17,3),0) -> 0 | L17: =+IFERROR(ABS(K17),"ok") -> 0 | M17: =+IF(L17="ok",J17,0) -> 0 | O17: =+M17+N17 -> 0 | S17: 104 | T17: 1 | U17: 0 | V17: MONEDA NACIONAL | W17: 50825584 | X17: 6.607306e+08 | Y17: -6.6930136e+08 | Z17: =+O17 -> 0 | AG17: =+CONCATENATE(S17,T17,V17) -> 1041MONEDA NACIONAL | AH17: =+VLOOKUP(AG17,Catálogo!E:F,2,0) -> #N/A | AI17: =+VLOOKUP(AG17,Catálogo!E:G,3,0) -> 0
A18: 104 | B18: 1 | C18: 1 | D18: ACTINVER 8344681 CUENTA GENERAL | E18: 37.97 | F18: 2.1565824e+08 | G18: -2.1565827e+08 | H18: 4.82 | J18: =+ROUND(H18/1000,0) -> 0 | K18: =+IFERROR(LEFT(AH18,3),0) -> Efe | L18: =+IFERROR(ABS(K18),"ok") -> ok | M18: =+IF(L18="ok",J18,0) -> 0 | O18: =+M18+N18 -> 0 | S18: 104 | T18: 1 | U18: 1 | V18: ACTINVER 8344681 CUENTA GENERAL | W18: 37.97 | X18: 2.1565824e+08 | Y18: -2.1565827e+08 | Z18: =+O18 -> 0 | AG18: =+CONCATENATE(S18,T18,V18) -> 1041ACTINVER 8344681 CUENTA GENERAL | AH18: =+VLOOKUP(AG18,Catálogo!E:F,2,0) -> Efectivo y equivalentes de efectivo | AI18: =+VLOOKUP(AG18,Catálogo!E:G,3,0) -> Inversiones en valores realizables
A19: 104 | B19: 1 | C19: 2 | D19: ACTINVER 8344681 COMPLEMENTARIA | E19: 14209863 | F19: 9296193 | G19: -14209863 | H19: 9296193 | J19: =+ROUND(H19/1000,0) -> 9296 | K19: =+IFERROR(LEFT(AH19,3),0) -> Efe | L19: =+IFERROR(ABS(K19),"ok") -> ok | M19: =+IF(L19="ok",J19,0) -> 9296 | O19: =+M19+N19 -> 9296 | S19: 104 | T19: 1 | U19: 2 | V19: ACTINVER 8344681 COMPLEMENTARIA | W19: 14209863 | X19: 9296193 | Y19: -14209863 | Z19: =+O19 -> 9296 | AG19: =+CONCATENATE(S19,T19,V19) -> 1041ACTINVER 8344681 COMPLEMENTARIA | AH19: =+VLOOKUP(AG19,Catálogo!E:F,2,0) -> Efectivo y equivalentes de efectivo | AI19: =+VLOOKUP(AG19,Catálogo!E:G,3,0) -> Inversiones en valores realizables
A20: 104 | B20: 1 | C20: 3 | D20: ACTINVER 5371322 CUENTA GENERAL | E20: 63.87 | F20: 3.5478633e+08 | G20: -3.5478633e+08 | H20: 63.24 | J20: =+ROUND(H20/1000,0) -> 0 | K20: =+IFERROR(LEFT(AH20,3),0) -> Efe | L20: =+IFERROR(ABS(K20),"ok") -> ok | M20: =+IF(L20="ok",J20,0) -> 0 | O20: =+M20+N20 -> 0 | S20: 104 | T20: 1 | U20: 3 | V20: ACTINVER 5371322 CUENTA GENERAL | W20: 63.87 | X20: 3.5478633e+08 | Y20: -3.5478633e+08 | Z20: =+O20 -> 0 | AG20: =+CONCATENATE(S20,T20,V20) -> 1041ACTINVER 5371322 CUENTA GENERAL | AH20: =+VLOOKUP(AG20,Catálogo!E:F,2,0) -> Efectivo y equivalentes de efectivo | AI20: =+VLOOKUP(AG20,Catálogo!E:G,3,0) -> Inversiones en valores realizables
A21: 104 | B21: 1 | C21: 4 | D21: ACTINVER CTA 5371322 COMPLEMENTARIA | E21: 19570563 | F21: 12794513 | G21: -19570563 | H21: 12794513 | J21: =+ROUND(H21/1000,0) -> 12795 | K21: =+IFERROR(LEFT(AH21,3),0) -> Efe | L21: =+IFERROR(ABS(K21),"ok") -> ok | M21: =+IF(L21="ok",J21,0) -> 12795 | O21: =+M21+N21 -> 12795 | S21: 104 | T21: 1 | U21: 4 | V21: ACTINVER CTA 5371322 COMPLEMENTARIA | W21: 19570563 | X21: 12794513 | Y21: -19570563 | Z21: =+O21 -> 12795 | AG21: =+CONCATENATE(S21,T21,V21) -> 1041ACTINVER CTA 5371322 COMPLEMENTARIA | AH21: =+VLOOKUP(AG21,Catálogo!E:F,2,0) -> Efectivo y equivalentes de efectivo | AI21: =+VLOOKUP(AG21,Catálogo!E:G,3,0) -> Inversiones en valores realizables
A22: 104 | B22: 1 | C22: 5 | D22: INVEX CTA 0705 COBRAZA INVER | E22: 0 | F22: 44864604 | G22: -44864604 | H22: 0 | J22: =+ROUND(H22/1000,0) -> 0 | K22: =+IFERROR(LEFT(AH22,3),0) -> Efe | L22: =+IFERROR(ABS(K22),"ok") -> ok | M22: =+IF(L22="ok",J22,0) -> 0 | O22: =+M22+N22 -> 0 | S22: 104 | T22: 1 | U22: 5 | V22: INVEX CTA 0705 COBRAZA INVER | W22: 0 | X22: 44864604 | Y22: -44864604 | Z22: =+O22 -> 0 | AG22: =+CONCATENATE(S22,T22,V22) -> 1041INVEX CTA 0705 COBRAZA INVER | AH22: =+VLOOKUP(AG22,Catálogo!E:F,2,0) -> Efectivo y equivalentes de efectivo | AI22: =+VLOOKUP(AG22,Catálogo!E:G,3,0) -> Inversiones en valores realizables
... A26: 109 | B26: 0 | C26: 0 | D26: DEUDORES DIVERSOS | E26: 28247873 | F26: 2399820.4 | G26: -11816669 | H26: 18831025 | J26: =+ROUND(H26/1000,0) -> 18831 | K26: =+IFERROR(LEFT(AH26,3),0) -> 0 | L26: =+IFERROR(ABS(K26),"ok") -> 0 | M26: =+IF(L26="ok",J26,0) -> 0 | O26: =+M26+N26 -> 0 | S26: 109 | T26: 0 | U26: 0 | V26: DEUDORES DIVERSOS | W26: 28247873 | X26: 2399820.4 | Y26: -11816669 | Z26: =+O26 -> 0 | AG26: =+CONCATENATE(S26,T26,V26) -> 1090DEUDORES DIVERSOS | AH26: =+VLOOKUP(AG26,Catálogo!E:F,2,0) -> #N/A | AI26: =+VLOOKUP(AG26,Catálogo!E:G,3,0) -> 0
A27: 109 | B27: 1 | C27: 0 | D27: DEUDORES DIVERSOS M.N. | E27: 28247873 | F27: 2399820.4 | G27: -11816669 | H27: 18831025 | J27: =+ROUND(H27/1000,0) -> 18831 | K27: =+IFERROR(LEFT(AH27,3),0) -> Deu | L27: =+IFERROR(ABS(K27),"ok") -> ok | M27: =+IF(L27="ok",J27,0) -> 18831 | N27: 1 | O27: =+M27+N27 -> 18832 | S27: 109 | T27: 1 | U27: 0 | V27: DEUDORES DIVERSOS M.N. | W27: 28247873 | X27: 2399820.4 | Y27: -11816669 | Z27: =+O27 -> 18832 | AG27: =+CONCATENATE(S27,T27,V27) -> 1091DEUDORES DIVERSOS M.N. | AH27: =+VLOOKUP(AG27,Catálogo!E:F,2,0) -> Deudores diversos y otras cuentas por cobrar
A28: 113 | B28: 0 | C28: 0 | D28: ANTICIPO DE IMPUESTOS | E28: 271215.91 | F28: 19646.59 | G28: 0 | H28: 290862.5 | J28: =+ROUND(H28/1000,0) -> 291 | K28: =+IFERROR(LEFT(AH28,3),0) -> 0 | L28: =+IFERROR(ABS(K28),"ok") -> 0 | M28: =+IF(L28="ok",J28,0) -> 0 | O28: =+M28+N28 -> 0 | S28: 113 | T28: 0 | U28: 0 | V28: ANTICIPO DE IMPUESTOS | W28: 271215.91 | X28: 19646.59 | Y28: 0 | Z28: =+O28 -> 0 | AG28: =+CONCATENATE(S28,T28,V28) -> 1130ANTICIPO DE IMPUESTOS | AH28: =+VLOOKUP(AG28,Catálogo!E:F,2,0) -> #N/A | AI28: =+VLOOKUP(AG28,Catálogo!E:G,3,0) -> 0
A29: 113 | B29: 1 | C29: 0 | D29: ISR | E29: 271215.91 | F29: 19646.59 | G29: 0 | H29: 290862.5 | J29: =+ROUND(H29/1000,0) -> 291 | K29: =+IFERROR(LEFT(AH29,3),0) -> 0 | L29: =+IFERROR(ABS(K29),"ok") -> 0 | M29: =+IF(L29="ok",J29,0) -> 0 | O29: =+M29+N29 -> 0 | S29: 113 | T29: 1 | U29: 0 | V29: ISR | W29: 271215.91 | X29: 19646.59 | Y29: 0 | Z29: =+O29 -> 0 | AG29: =+CONCATENATE(S29,T29,V29) -> 1131ISR | AH29: =+VLOOKUP(AG29,Catálogo!E:F,2,0) -> #N/A | AI29: =+VLOOKUP(AG29,Catálogo!E:G,3,0) -> 0
A30: 113 | B30: 1 | C30: 1 | D30: ISR PAGO PROVISIONALES | E30: 12.15 | F30: 0 | G30: 0 | H30: 12.15 | J30: =+ROUND(H30/1000,0) -> 0 | K30: =+IFERROR(LEFT(AH30,3),0) -> Imp | L30: =+IFERROR(ABS(K30),"ok") -> ok | M30: =+IF(L30="ok",J30,0) -> 0 | O30: =+M30+N30 -> 0 | S30: 113 | T30: 1 | U30: 1 | V30: ISR PAGO PROVISIONALES | W30: 12.15 | X30: 0 | Y30: 0 | Z30: =+O30 -> 0 | AG30: =+CONCATENATE(S30,T30,V30) -> 1131ISR PAGO PROVISIONALES | AH30: =+VLOOKUP(AG30,Catálogo!E:F,2,0) -> Impuestos por recuperar | AI30: =+VLOOKUP(AG30,Catálogo!E:G,3,0) -> ISR Retenido
A31: 113 | B31: 1 | C31: 2 | D31: ISR RETENCIONES BANCOS | E31: 271203.76 | F31: 19646.59 | G31: 0 | H31: 290850.35 | J31: =+ROUND(H31/1000,0) -> 291 | K31: =+IFERROR(LEFT(AH31,3),0) -> Imp | L31: =+IFERROR(ABS(K31),"ok") -> ok | M31: =+IF(L31="ok",J31,0) -> 291 | O31: =+M31+N31 -> 291 | S31: 113 | T31: 1 | U31: 2 | V31: ISR RETENCIONES BANCOS | W31: 271203.76 | X31: 19646.59 | Y31: 0 | Z31: =+O31 -> 291 | AG31: =+CONCATENATE(S31,T31,V31) -> 1131ISR RETENCIONES BANCOS | AH31: =+VLOOKUP(AG31,Catálogo!E:F,2,0) -> Impuestos por recuperar | AI31: =+VLOOKUP(AG31,Catálogo!E:G,3,0) -> ISR Retenido
A32: 114 | B32: 0 | C32: 0 | D32: IMPUESTOS A FAVOR | E32: 70226019 | F32: 2414987.7 | G32: -176335.02 | H32: 72464672 | J32: =+ROUND(H32/1000,0) -> 72465 | K32: =+IFERROR(LEFT(AH32,3),0) -> 0 | L32: =+IFERROR(ABS(K32),"ok") -> 0 | M32: =+IF(L32="ok",J32,0) -> 0 | O32: =+M32+N32 -> 0 | S32: 114 | T32: 0 | U32: 0 | V32: IMPUESTOS A FAVOR | W32: 70226019 | X32: 2414987.7 | Y32: -176335.02 | Z32: =+O32 -> 0 | AG32: =+CONCATENATE(S32,T32,V32) -> 1140IMPUESTOS A FAVOR | AH32: =+VLOOKUP(AG32,Catálogo!E:F,2,0) -> #N/A | AI32: =+VLOOKUP(AG32,Catálogo!E:G,3,0) -> 0
A33: 114 | B33: 1 | C33: 0 | D33: IVA SALDO A FAVOR | E33: 70226019 | F33: 2414987.7 | G33: -176335.02 | H33: 72464672 | J33: =+ROUND(H33/1000,0) -> 72465 | K33: =+IFERROR(LEFT(AH33,3),0) -> 0 | L33: =+IFERROR(ABS(K33),"ok") -> 0 | M33: =+IF(L33="ok",J33,0) -> 0 | O33: =+M33+N33 -> 0 | S33: 114 | T33: 1 | U33: 0 | V33: IVA SALDO A FAVOR | W33: 70226019 | X33: 2414987.7 | Y33: -176335.02 | Z33: =+O33 -> 0 | AG33: =+CONCATENATE(S33,T33,V33) -> 1141IVA SALDO A FAVOR | AH33: =+VLOOKUP(AG33,Catálogo!E:F,2,0) -> #N/A | AI33: =+VLOOKUP(AG33,Catálogo!E:G,3,0) -> 0
A34: 114 | B34: 1 | C34: 1 | D34: IVA SALDO A FAVOR AL 16% | E34: 70226019 | F34: 2414987.7 | G34: -176335.02 | H34: 72464672 | J34: =+ROUND(H34/1000,0) -> 72465 | K34: =+IFERROR(LEFT(AH34,3),0) -> Inv | L34: =+IFERROR(ABS(K34),"ok") -> ok | M34: =+IF(L34="ok",J34,0) -> 72465 | O34: =+M34+N34 -> 72465 | S34: 114 | T34: 1 | U34: 1 | V34: IVA SALDO A FAVOR AL 16% | W34: 70226019 | X34: 2414987.7 | Y34: -176335.02 | Z34: =+O34 -> 72465 | AG34: =+CONCATENATE(S34,T34,V34) -> 1141IVA SALDO A FAVOR AL 16% | AH34: =+VLOOKUP(AG34,Catálogo!E:F,2,0) -> Inventarios inmobiliarios y costos pagados por anticipado | AI34: =+VLOOKUP(AG34,Catálogo!E:G,3,0) -> Impuesto al Valor Agregado
A35: 115 | B35: 0 | C35: 0 | D35: IMPUESTOS A FAVOR NO CAUSADO | E35: 6602611.3 | F35: 2054143.3 | G35: -2447241.6 | H35: 6209513 | J35: =+ROUND(H35/1000,0) -> 6210 | K35: =+IFERROR(LEFT(AH35,3),0) -> 0 | L35: =+IFERROR(ABS(K35),"ok") -> 0 | M35: =+IF(L35="ok",J35,0) -> 0 | O35: =+M35+N35 -> 0 | S35: 115 | T35: 0 | U35: 0 | V35: IMPUESTOS A FAVOR NO CAUSADO | W35: 6602611.3 | X35: 2054143.3 | Y35: -2447241.6 | Z35: =+O35 -> 0 | AG35: =+CONCATENATE(S35,T35,V35) -> 1150IMPUESTOS A FAVOR NO CAUSADO | AH35: =+VLOOKUP(AG35,Catálogo!E:F,2,0) -> #N/A | AI35: =+VLOOKUP(AG35,Catálogo!E:G,3,0) -> 0
A36: 115 | B36: 1 | C36: 0 | D36: IVA ACREDITABLE NO PAGADO | E36: 6602611.3 | F36: 2054143.3 | G36: -2447241.6 | H36: 6209513 | J36: =+ROUND(H36/1000,0) -> 6210 | K36: =+IFERROR(LEFT(AH36,3),0) -> 0 | L36: =+IFERROR(ABS(K36),"ok") -> 0 | M36: =+IF(L36="ok",J36,0) -> 0 | O36: =+M36+N36 -> 0 | S36: 115 | T36: 1 | U36: 0 | V36: IVA ACREDITABLE NO PAGADO | W36: 6602611.3 | X36: 2054143.3 | Y36: -2447241.6 | Z36: =+O36 -> 0 | AG36: =+CONCATENATE(S36,T36,V36) -> 1151IVA ACREDITABLE NO PAGADO | AH36: =+VLOOKUP(AG36,Catálogo!E:F,2,0) -> #N/A | AI36: =+VLOOKUP(AG36,Catálogo!E:G,3,0) -> 0
A37: 115 | B37: 1 | C37: 1 | D37: IVA ACREDITABLE NO PAGADO AL 16% | E37: 6602611.3 | F37: 2054143.3 | G37: -2447241.6 | H37: 6209513 | J37: =+ROUND(H37/1000,0) -> 6210 | K37: =+IFERROR(LEFT(AH37,3),0) -> Deu | L37: =+IFERROR(ABS(K37),"ok") -> ok | M37: =+IF(L37="ok",J37,0) -> 6210 | O37: =+M37+N37 -> 6210 | S37: 115 | T37: 1 | U37: 1 | V37: IVA ACREDITABLE NO PAGADO AL 16% | W37: 6602611.3 | X37: 2054143.3 | Y37: -2447241.6 | Z37: =+O37 -> 6210 | AG37: =+CONCATENATE(S37,T37,V37) -> 1151IVA ACREDITABLE NO PAGADO AL 16% | AH37: =+VLOOKUP(AG37,Catálogo!E:F,2,0) -> Deudores diversos y otras cuentas por cobrar | AI37: =+VLOOKUP(AG37,Catálogo!E:G,3,0) -> 0
A38: 118 | B38: 0 | C38: 0 | D38: PAGOS ANTICIPADOS | E38: 0 | F38: 250000 | G38: -21232.88 | H38: 228767.12 | J38: =+ROUND(H38/1000,0) -> 229 | K38: =+IFERROR(LEFT(AH38,3),0) -> 0 | L38: =+IFERROR(ABS(K38),"ok") -> 0 | M38: =+IF(L38="ok",J38,0) -> 0 | O38: =+M38+N38 -> 0 | S38: 118 | T38: 0 | U38: 0 | V38: PAGOS ANTICIPADOS | W38: 0 | X38: 250000 | Y38: -21232.88 | Z38: =+O38 -> 0 | AG38: =+CONCATENATE(S38,T38,V38) -> 1180PAGOS ANTICIPADOS | AH38: =+VLOOKUP(AG38,Catálogo!E:F,2,0) -> 0 | AI38: =+VLOOKUP(AG38,Catálogo!E:G,3,0) -> 0
A39: 118 | B39: 2 | C39: 0 | D39: PROVEEDORES | E39: 0 | F39: 250000 | G39: -21232.88 | H39: 228767.12 | J39: =+ROUND(H39/1000,0) -> 229 | K39: =+IFERROR(LEFT(AH39,3),0) -> 0 | L39: =+IFERROR(ABS(K39),"ok") -> 0 | M39: =+IF(L39="ok",J39,0) -> 0 | O39: =+M39+N39 -> 0 | S39: 118 | T39: 2 | U39: 0 | V39: PROVEEDORES | W39: 0 | X39: 250000 | Y39: -21232.88 | Z39: =+O39 -> 0 | AG39: =+CONCATENATE(S39,T39,V39) -> 1182PROVEEDORES | AH39: =+VLOOKUP(AG39,Catálogo!E:F,2,0) -> 0 | AI39: =+VLOOKUP(AG39,Catálogo!E:G,3,0) -> 0
... A75: 123 | B75: 7 | C75: 123 | D75: GASTOS ADMINISTRATIVOS OBRA | E75: 74914.71 | F75: 21232.88 | G75: 0 | H75: 96147.59 | J75: =+ROUND(H75/1000,0) -> 96 | K75: =+IFERROR(LEFT(AH75,3),0) -> Inv | L75: =+IFERROR(ABS(K75),"ok") -> ok | M75: =+IF(L75="ok",J75,0) -> 96 | O75: =+M75+N75 -> 96 | S75: 123 | T75: 7 | U75: 123 | V75: GASTOS ADMINISTRATIVOS OBRA | W75: 74914.71 | X75: 21232.88 | Y75: 0 | Z75: =+O75 -> 96 | AG75: =+CONCATENATE(S75,T75,V75) -> 1237GASTOS ADMINISTRATIVOS OBRA | AH75: =+VLOOKUP(AG75,Catálogo!E:F,2,0) -> Inventarios inmobiliarios y costos pagados por anticipado | AI75: =+VLOOKUP(AG75,Catálogo!E:G,3,0) -> Construcción en proceso (ii)
A76: 123 | B76: 9 | C76: 0 | D76: COMERCIALIZACION. | E76: 20180706 | F76: 0 | G76: -299999.98 | H76: 19880706 | J76: =+ROUND(H76/1000,0) -> 19881 | K76: =+IFERROR(LEFT(AH76,3),0) -> 0 | L76: =+IFERROR(ABS(K76),"ok") -> 0 | M76: =+IF(L76="ok",J76,0) -> 0 | O76: =+M76+N76 -> 0 | S76: 123 | T76: 9 | U76: 0 | V76: COMERCIALIZACION. | W76: 20180706 | X76: 0 | Y76: -299999.98 | Z76: =+O76 -> 0 | AG76: =+CONCATENATE(S76,T76,V76) -> 1239 COMERCIALIZACION. | AH76: =+VLOOKUP(AG76,Catálogo!E:F,2,0) -> #N/A
A77: 123 | B77: 9 | C77: 1 | D77: COMERCIALIZACION | E77: 20180706 | F77: 0 | G77: -299999.98 | H77: 19880706 | J77: =+ROUND(H77/1000,0) -> 19881 | K77: =+IFERROR(LEFT(AH77,3),0) -> Inv | L77: =+IFERROR(ABS(K77),"ok") -> ok | M77: =+IF(L77="ok",J77,0) -> 19881 | O77: =+M77+N77 -> 19881 | S77: 123 | T77: 9 | U77: 1 | V77: COMERCIALIZACION | W77: 20180706 | X77: 0 | Y77: -299999.98 | Z77: =+O77 -> 19881 | AG77: =+CONCATENATE(S77,T77,V77) -> 1239COMERCIALIZACION | AH77: =+VLOOKUP(AG77,Catálogo!E:F,2,0) -> Inventarios inmobiliarios y costos pagados por anticipado | AI77: =+VLOOKUP(AG77,Catálogo!E:G,3,0) -> Gastos administrativos y de comercialización (iv)
A78: 124 | B78: 0 | C78: 0 | D78: MOBILIARIO Y EQUIPO DE OFICINA | E78: 47000.28 | F78: 0 | G78: -405.18 | H78: 46595.1 | J78: =+ROUND(H78/1000,0) -> 47 | K78: =+IFERROR(LEFT(AH78,3),0) -> 0 | L78: =+IFERROR(ABS(K78),"ok") -> 0 | M78: =+IF(L78="ok",J78,0) -> 0 | O78: =+M78+N78 -> 0 | S78: 124 | T78: 0 | U78: 0 | V78: MOBILIARIO Y EQUIPO DE OFICINA | W78: 47000.28 | X78: 0 | Y78: -405.18 | Z78: =+O78 -> 0 | AG78: =+CONCATENATE(S78,T78,V78) -> 1240MOBILIARIO Y EQUIPO DE OFICINA | AH78: =+VLOOKUP(AG78,Catálogo!E:F,2,0) -> 0 | AI78: =+VLOOKUP(AG78,Catálogo!E:G,3,0) -> 0
...

Sheet BalanzaAnterior
O7: =+SUM(O11:O251) -> 1
A10: Cuenta | B10: Scta | C10: SSCta | D10: Descripción | E10: Saldo Inicial | F10: Cargos | G10: Abonos | H10: Saldo Actual | K10: Quitar duplicados y cuentas de mayor | N10: Determinar saldos ajustados listos para trabajar | R10: Cuenta | S10: Scta | T10: SSCta | U10: Descripción | V10: Saldo Inicial | W10: Cargos | X10: Abonos | Y10: Saldo Actual | AE10: Rubro | AF10: Nota
A11: 103 | B11: 0 | C11: 0 | D11: BANCOS | E11: 22923.02 | F11: 3.5605501e+08 | G11: -3.5490394e+08 | H11: 1173988.2 | J11: =+ROUND(H11/1000,0) -> 1174 | K11: =+IFERROR(LEFT(AE11,3),0) -> 0 | L11: =+IFERROR(ABS(K11),"ok") -> 0 | M11: =+IF(L11="ok",J11,0) -> 0 | O11: =+M11+N11 -> 0 | R11: 103 | S11: 0 | T11: 0 | U11: BANCOS | V11: 22923.02 | W11: 3.5605501e+08 | X11: -3.5490394e+08 | Y11: =+O11 -> 0 | AD11: =+CONCATENATE(A11,B11,D11) -> 1030BANCOS | AE11: =+VLOOKUP(AD11,Catálogo!E:F,2,0) -> #N/A | AF11: =+VLOOKUP(AD11,Catálogo!E:G,3,0) -> 0
A12: 103 | B12: 1 | C12: 0 | D12: MONEDA NACIONAL | E12: 22923.02 | F12: 3.5605501e+08 | G12: -3.5490394e+08 | H12: 1173988.2 | J12: =+ROUND(H12/1000,0) -> 1174 | K12: =+IFERROR(LEFT(AE12,3),0) -> 0 | L12: =+IFERROR(ABS(K12),"ok") -> 0 | M12: =+IF(L12="ok",J12,0) -> 0 | O12: =+M12+N12 -> 0 | R12: 103 | S12: 1 | T12: 0 | U12: MONEDA NACIONAL | V12: 22923.02 | W12: 3.5605501e+08 | X12: -3.5490394e+08 | Y12: =+O12 -> 0 | AD12: =+CONCATENATE(A12,B12,D12) -> 1031MONEDA NACIONAL | AE12: =+VLOOKUP(AD12,Catálogo!E:F,2,0) -> #N/A | AF12: =+VLOOKUP(AD12,Catálogo!E:G,3,0) -> 0
A13: 103 | B13: 1 | C13: 2 | D13: BBVA CTA 0116008208 | E13: 22923.02 | F13: 2.4509195e+08 | G13: -2.4424089e+08 | H13: 873988.17 | J13: =+ROUND(H13/1000,0) -> 874 | K13: =+IFERROR(LEFT(AE13,3),0) -> Efe | L13: =+IFERROR(ABS(K13),"ok") -> ok | M13: =+IF(L13="ok",J13,0) -> 874 | O13: =+M13+N13 -> 874 | R13: 103 | S13: 1 | T13: 2 | U13: BBVA CTA 0116008208 | V13: 22923.02 | W13: 2.4509195e+08 | X13: -2.4424089e+08 | Y13: =+O13 -> 874 | AD13: =+CONCATENATE(A13,B13,D13) -> 1031BBVA CTA 0116008208 | AE13: =+VLOOKUP(AD13,Catálogo!E:F,2,0) -> Efectivo y equivalentes de efectivo | AF13: =+VLOOKUP(AD13,Catálogo!E:G,3,0) -> Depósitos en cuenta de cheques
A14: 103 | B14: 1 | C14: 5 | D14: INVEX CTA 05661 COBRANZA | E14: 0 | F14: 98632558 | G14: -98332558 | H14: 300000 | J14: =+ROUND(H14/1000,0) -> 300 | K14: =+IFERROR(LEFT(AE14,3),0) -> Efe | L14: =+IFERROR(ABS(K14),"ok") -> ok | M14: =+IF(L14="ok",J14,0) -> 300 | O14: =+M14+N14 -> 300 | R14: 103 | S14: 1 | T14: 5 | U14: INVEX CTA 05661 COBRANZA | V14: 0 | W14: 98632558 | X14: -98332558 | Y14: =+O14 -> 300 | AD14: =+CONCATENATE(A14,B14,D14) -> 1031INVEX CTA 05661 COBRANZA | AE14: =+VLOOKUP(AD14,Catálogo!E:F,2,0) -> Efectivo y equivalentes de efectivo | AF14: =+VLOOKUP(AD14,Catálogo!E:G,3,0) -> Depósitos en cuenta de cheques
A15: 103 | B15: 1 | C15: 6 | D15: INVEX CTA 05662 RESERVA | E15: 0 | F15: 12330500 | G15: -12330500 | H15: 0 | J15: =+ROUND(H15/1000,0) -> 0 | K15: =+IFERROR(LEFT(AE15,3),0) -> Efe | L15: =+IFERROR(ABS(K15),"ok") -> ok | M15: =+IF(L15="ok",J15,0) -> 0 | O15: =+M15+N15 -> 0 | R15: 103 | S15: 1 | T15: 6 | U15: INVEX CTA 05662 RESERVA | V15: 0 | W15: 12330500 | X15: -12330500 | Y15: =+O15 -> 0 | AD15: =+CONCATENATE(A15,B15,D15) -> 1031INVEX CTA 05662 RESERVA | AE15: =+VLOOKUP(AD15,Catálogo!E:F,2,0) -> Efectivo y equivalentes de efectivo | AF15: =+VLOOKUP(AD15,Catálogo!E:G,3,0) -> Depósitos en cuenta de cheques
A16: 104 | B16: 0 | C16: 0 | D16: INVERSIONES SISTEMA FINANCIERO | E16: 8699.59 | F16: 2.2878173e+09 | G16: -2.2423491e+09 | H16: 45476852 | J16: =+ROUND(H16/1000,0) -> 45477 | K16: =+IFERROR(LEFT(AE16,3),0) -> 0 | L16: =+IFERROR(ABS(K16),"ok") -> 0 | M16: =+IF(L16="ok",J16,0) -> 0 | O16: =+M16+N16 -> 0 | R16: 104 | S16: 0 | T16: 0 | U16: INVERSIONES SISTEMA FINANCIERO | V16: 8699.59 | W16: 2.2878173e+09 | X16: -2.2423491e+09 | Y16: =+O16 -> 0 | AD16: =+CONCATENATE(A16,B16,D16) -> 1040INVERSIONES SISTEMA FINANCIERO | AE16: =+VLOOKUP(AD16,Catálogo!E:F,2,0) -> #N/A | AF16: =+VLOOKUP(AD16,Catálogo!E:G,3,0) -> 0
A17: 104 | B17: 1 | C17: 0 | D17: MONEDA NACIONAL | E17: 8699.59 | F17: 2.2878173e+09 | G17: -2.2423491e+09 | H17: 45476852 | J17: =+ROUND(H17/1000,0) -> 45477 | K17: =+IFERROR(LEFT(AE17,3),0) -> 0 | L17: =+IFERROR(ABS(K17),"ok") -> 0 | M17: =+IF(L17="ok",J17,0) -> 0 | O17: =+M17+N17 -> 0 | R17: 104 | S17: 1 | T17: 0 | U17: MONEDA NACIONAL | V17: 8699.59 | W17: 2.2878173e+09 | X17: -2.2423491e+09 | Y17: =+O17 -> 0 | AD17: =+CONCATENATE(A17,B17,D17) -> 1041MONEDA NACIONAL | AE17: =+VLOOKUP(AD17,Catálogo!E:F,2,0) -> #N/A | AF17: =+VLOOKUP(AD17,Catálogo!E:G,3,0) -> 0
A18: 104 | B18: 1 | C18: 1 | D18: ACTINVER 8344681 CUENTA GENERAL | E18: 3.55 | F18: 1.2228753e+09 | G18: -1.2223359e+09 | H18: 539403.32 | J18: =+ROUND(H18/1000,0) -> 539 | K18: =+IFERROR(LEFT(AE18,3),0) -> Efe | L18: =+IFERROR(ABS(K18),"ok") -> ok | M18: =+IF(L18="ok",J18,0) -> 539 | O18: =+M18+N18 -> 539 | R18: 104 | S18: 1 | T18: 1 | U18: ACTINVER 8344681 CUENTA GENERAL | V18: 3.55 | W18: 1.2228753e+09 | X18: -1.2223359e+09 | Y18: =+O18 -> 539 | AD18: =+CONCATENATE(A18,B18,D18) -> 1041ACTINVER 8344681 CUENTA GENERAL | AE18: =+VLOOKUP(AD18,Catálogo!E:F,2,0) -> Efectivo y equivalentes de efectivo | AF18: =+VLOOKUP(AD18,Catálogo!E:G,3,0) -> Inversiones en valores realizables
A19: 104 | B19: 1 | C19: 2 | D19: ACTINVER 8344681 COMPLEMENTARIA | E19: 8696.04 | F19: 34345824 | G19: -2000694.7 | H19: 32353825 | J19: =+ROUND(H19/1000,0) -> 32354 | K19: =+IFERROR(LEFT(AE19,3),0) -> Efe | L19: =+IFERROR(ABS(K19),"ok") -> ok | M19: =+IF(L19="ok",J19,0) -> 32354 | O19: =+M19+N19 -> 32354 | R19: 104 | S19: 1 | T19: 2 | U19: ACTINVER 8344681 COMPLEMENTARIA | V19: 8696.04 | W19: 34345824 | X19: -2000694.7 | Y19: =+O19 -> 32354 | AD19: =+CONCATENATE(A19,B19,D19) -> 1041ACTINVER 8344681 COMPLEMENTARIA | AE19: =+VLOOKUP(AD19,Catálogo!E:F,2,0) -> Efectivo y equivalentes de efectivo | AF19: =+VLOOKUP(AD19,Catálogo!E:G,3,0) -> Inversiones en valores realizables
A20: 104 | B20: 1 | C20: 3 | D20: ACTINVER 5371322 CUENTA GENERAL | E20: 0 | F20: 6.2686253e+08 | G20: -6.268607e+08 | H20: 1825.57 | J20: =+ROUND(H20/1000,0) -> 2 | K20: =+IFERROR(LEFT(AE20,3),0) -> Efe | L20: =+IFERROR(ABS(K20),"ok") -> ok | M20: =+IF(L20="ok",J20,0) -> 2 | O20: =+M20+N20 -> 2 | R20: 104 | S20: 1 | T20: 3 | U20: ACTINVER 5371322 CUENTA GENERAL | V20: 0 | W20: 6.2686253e+08 | X20: -6.268607e+08 | Y20: =+O20 -> 2 | AD20: =+CONCATENATE(A20,B20,D20) -> 1041ACTINVER 5371322 CUENTA GENERAL | AE20: =+VLOOKUP(AD20,Catálogo!E:F,2,0) -> Efectivo y equivalentes de efectivo | AF20: =+VLOOKUP(AD20,Catálogo!E:G,3,0) -> Inversiones en valores realizables
A21: 104 | B21: 1 | C21: 4 | D21: ACTINVER CTA 5371322 COMPLEMENTARIA | E21: 0 | F21: 11511438 | G21: -11511438 | H21: 0 | J21: =+ROUND(H21/1000,0) -> 0 | K21: =+IFERROR(LEFT(AE21,3),0) -> Efe | L21: =+IFERROR(ABS(K21),"ok") -> ok | M21: =+IF(L21="ok",J21,0) -> 0 | O21: =+M21+N21 -> 0 | R21: 104 | S21: 1 | T21: 4 | U21: ACTINVER CTA 5371322 COMPLEMENTARIA | V21: 0 | W21: 11511438 | X21: -11511438 | Y21: =+O21 -> 0 | AD21: =+CONCATENATE(A21,B21,D21) -> 1041ACTINVER CTA 5371322 COMPLEMENTARIA | AE21: =+VLOOKUP(AD21,Catálogo!E:F,2,0) -> Efectivo y equivalentes de efectivo | AF21: =+VLOOKUP(AD21,Catálogo!E:G,3,0) -> Inversiones en valores realizables
A22: 104 | B22: 1 | C22: 5 | D22: INVEX CTA 0705 COBRA INVER | E22: 0 | F22: 88535259 | G22: -88535259 | H22: 0 | J22: =+ROUND(H22/1000,0) -> 0 | K22: =+IFERROR(LEFT(AE22,3),0) -> Efe | L22: =+IFERROR(ABS(K22),"ok") -> ok | M22: =+IF(L22="ok",J22,0) -> 0 | O22: =+M22+N22 -> 0 | R22: 104 | S22: 1 | T22: 5 | U22: INVEX CTA 0705 COBRA INVER | V22: 0 | W22: 88535259 | X22: -88535259 | Y22: =+O22 -> 0 | AD22: =+CONCATENATE(A22,B22,D22) -> 1041INVEX CTA 0705 COBRA INVER | AE22: =+VLOOKUP(AD22,Catálogo!E:F,2,0) -> Efectivo y equivalentes de efectivo | AF22: =+VLOOKUP(AD22,Catálogo!E:G,3,0) -> Inversiones en valores realizables
A23: 104 | B23: 1 | C23: 6 | D23: INVEX CTA 0705 COBRA INVER COMPLEMENTARI | E23: 0 | F23: 9657687.7 | G23: -9657687.7 | H23: 0 | J23: =+ROUND(H23/1000,0) -> 0 | K23: =+IFERROR(LEFT(AE23,3),0) -> Efe | L23: =+IFERROR(ABS(K23),"ok") -> ok | M23: =+IF(L23="ok",J23,0) -> 0 | O23: =+M23+N23 -> 0 | R23: 104 | S23: 1 | T23: 6 | U23: INVEX CTA 0705 COBRA INVER COMPLEMENTARI | V23: 0 | W23: 9657687.7 | X23: -9657687.7 | Y23: =+O23 -> 0 | AD23: =+CONCATENATE(A23,B23,D23) -> 1041INVEX CTA 0705 COBRA INVER COMPLEMENTARI | AE23: =+VLOOKUP(AD23,Catálogo!E:F,2,0) -> Efectivo y equivalentes de efectivo | AF23: =+VLOOKUP(AD23,Catálogo!E:G,3,0) -> Inversiones en valores realizables
A24: 104 | B24: 1 | C24: 7 | D24: INVEX CTA 0732 RESERVA INVER | E24: 0 | F24: 2.7035193e+08 | G24: -2.7035193e+08 | H24: 0.32 | J24: =+ROUND(H24/1000,0) -> 0 | K24: =+IFERROR(LEFT(AE24,3),0) -> Efe | L24: =+IFERROR(ABS(K24),"ok") -> ok | M24: =+IF(L24="ok",J24,0) -> 0 | O24: =+M24+N24 -> 0 | R24: 104 | S24: 1 | T24: 7 | U24: INVEX CTA 0732 RESERVA INVER | V24: 0 | W24: 2.7035193e+08 | X24: -2.7035193e+08 | Y24: =+O24 -> 0 | AD24: =+CONCATENATE(A24,B24,D24) -> 1041INVEX CTA 0732 RESERVA INVER | AE24: =+VLOOKUP(AD24,Catálogo!E:F,2,0) -> Efectivo y equivalentes de efectivo | AF24: ISR Retenido
A25: 104 | B25: 1 | C25: 8 | D25: INVEX CTA 0732 RESERVA INVER COMPLEMENTA | E25: 0 | F25: 23677356 | G25: -11095558 | H25: 12581798 | J25: =+ROUND(H25/1000,0) -> 12582 | K25: =+IFERROR(LEFT(AE25,3),0) -> Efe | L25: =+IFERROR(ABS(K25),"ok") -> ok | M25: =+IF(L25="ok",J25,0) -> 12582 | O25: =+M25+N25 -> 12582 | R25: 104 | S25: 1 | T25: 8 | U25: INVEX CTA 0732 RESERVA INVER COMPLEMENTA | V25: 0 | W25: 23677356 | X25: -11095558 | Y25: =+O25 -> 12582 | AD25: =+CONCATENATE(A25,B25,D25) -> 1041INVEX CTA 0732 RESERVA INVER COMPLEMENTA | AE25: =+VLOOKUP(AD25,Catálogo!E:F,2,0) -> Efectivo y equivalentes de efectivo | AF25: =+VLOOKUP(AD25,Catálogo!E:G,3,0) -> Inversiones en valores realizables
A26: 108 | B26: 0 | C26: 0 | D26: CLIENTES | E26: 0 | F26: 2848819.5 | G26: -2848819.5 | H26: 0 | J26: =+ROUND(H26/1000,0) -> 0 | K26: =+IFERROR(LEFT(AE26,3),0) -> 0 | L26: =+IFERROR(ABS(K26),"ok") -> 0 | M26: =+IF(L26="ok",J26,0) -> 0 | O26: =+M26+N26 -> 0 | R26: 108 | S26: 0 | T26: 0 | U26: CLIENTES | V26: 0 | W26: 2848819.5 | X26: -2848819.5 | Y26: =+O26 -> 0 | AD26: =+CONCATENATE(A26,B26,D26) -> 1080CLIENTES | AE26: =+VLOOKUP(AD26,Catálogo!E:F,2,0) -> #N/A | AF26: =+VLOOKUP(AD26,Catálogo!E:G,3,0) -> 0
A27: 108 | B27: 1 | C27: 0 | D27: CLIENTES M.N. | E27: 0 | F27: 2848819.5 | G27: -2848819.5 | H27: 0 | J27: =+ROUND(H27/1000,0) -> 0 | K27: =+IFERROR(LEFT(AE27,3),0) -> 0 | L27: =+IFERROR(ABS(K27),"ok") -> 0 | M27: =+IF(L27="ok",J27,0) -> 0 | O27: =+M27+N27 -> 0 | R27: 108 | S27: 1 | T27: 0 | U27: CLIENTES M.N. | V27: 0 | W27: 2848819.5 | X27: -2848819.5 | Y27: =+O27 -> 0 | AD27: =+CONCATENATE(A27,B27,D27) -> 1081CLIENTES M.N. | AE27: =+VLOOKUP(AD27,Catálogo!E:F,2,0) -> #N/A | AF27: Impuesto al Valor Agregado
A28: 109 | B28: 0 | C28: 0 | D28: DEUDORES DIVERSOS | E28: 15536081 | F28: 1.2598267e+08 | G28: -1.3156741e+08 | H28: 9951343.1 | J28: =+ROUND(H28/1000,0) -> 9951 | K28: =+IFERROR(LEFT(AE28,3),0) -> 0 | L28: =+IFERROR(ABS(K28),"ok") -> 0 | M28: =+IF(L28="ok",J28,0) -> 0 | O28: =+M28+N28 -> 0 | R28: 109 | S28: 0 | T28: 0 | U28: DEUDORES DIVERSOS | V28: 15536081 | W28: 1.2598267e+08 | X28: -1.3156741e+08 | Y28: =+O28 -> 0 | AD28: =+CONCATENATE(A28,B28,D28) -> 1090DEUDORES DIVERSOS | AE28: =+VLOOKUP(AD28,Catálogo!E:F,2,0) -> #N/A | AF28: =+VLOOKUP(AD28,Catálogo!E:G,3,0) -> 0
A29: 109 | B29: 1 | C29: 0 | D29: DEUDORES DIVERSOS M.N. | E29: 15536081 | F29: 1.2598267e+08 | G29: -1.3156741e+08 | H29: 9951343.1 | J29: =+ROUND(H29/1000,0) -> 9951 | K29: =+IFERROR(LEFT(AE29,3),0) -> Deu | L29: =+IFERROR(ABS(K29),"ok") -> ok | M29: =+IF(L29="ok",J29,0) -> 9951 | N29: =-SUM(M11:M251) -> 1 | O29: =+M29+N29 -> 9952 | R29: 109 | S29: 1 | T29: 0 | U29: DEUDORES DIVERSOS M.N. | V29: 15536081 | W29: 1.2598267e+08 | X29: -1.3156741e+08 | Y29: =+O29 -> 9952 | AD29: =+CONCATENATE(A29,B29,D29) -> 1091DEUDORES DIVERSOS M.N. | AE29: =+VLOOKUP(AD29,Catálogo!E:F,2,0) -> Deudores diversos y otras cuentas por cobrar | AF29: =+VLOOKUP(AD29,Catálogo!E:G,3,0) -> 0
A30: 113 | B30: 0 | C30: 0 | D30: ANTICIPO DE IMPUESTOS | E30: 7040.35 | F30: 8828.47 | G30: 0 | H30: 15868.82 | J30: =+ROUND(H30/1000,0) -> 16 | K30: =+IFERROR(LEFT(AE30,3),0) -> 0 | L30: =+IFERROR(ABS(K30),"ok") -> 0 | M30: =+IF(L30="ok",J30,0) -> 0 | O30: =+M30+N30 -> 0 | R30: 113 | S30: 0 | T30: 0 | U30: ANTICIPO DE IMPUESTOS | V30: 7040.35 | W30: 8828.47 | X30: 0 | Y30: =+O30 -> 0 | AD30: =+CONCATENATE(A30,B30,D30) -> 1130ANTICIPO DE IMPUESTOS | AE30: =+VLOOKUP(AD30,Catálogo!E:F,2,0) -> #N/A | AF30: =+VLOOKUP(AD30,Catálogo!E:G,3,0) -> 0
A31: 113 | B31: 1 | C31: 0 | D31: ISR | E31: 7040.35 | F31: 8828.47 | G31: 0 | H31: 15868.82 | J31: =+ROUND(H31/1000,0) -> 16 | K31: =+IFERROR(LEFT(AE31,3),0) -> 0 | L31: =+IFERROR(ABS(K31),"ok") -> 0 | M31: =+IF(L31="ok",J31,0) -> 0 | O31: =+M31+N31 -> 0 | R31: 113 | S31: 1 | T31: 0 | U31: ISR | V31: 7040.35 | W31: 8828.47 | X31: 0 | Y31: =+O31 -> 0 | AD31: =+CONCATENATE(A31,B31,D31) -> 1131ISR | AE31: =+VLOOKUP(AD31,Catálogo!E:F,2,0) -> #N/A | AF31: =+VLOOKUP(AD31,Catálogo!E:G,3,0) -> 0
A32: 113 | B32: 1 | C32: 1 | D32: ISR PAGO PROVISIONALES | E32: 0 | F32: 12.15 | G32: 0 | H32: 12.15 | J32: =+ROUND(H32/1000,0) -> 0 | K32: =+IFERROR(LEFT(AE32,3),0) -> Imp | L32: =+IFERROR(ABS(K32),"ok") -> ok | M32: =+IF(L32="ok",J32,0) -> 0 | O32: =+M32+N32 -> 0 | R32: 113 | S32: 1 | T32: 1 | U32: ISR PAGO PROVISIONALES | V32: 0 | W32: 12.15 | X32: 0 | Y32: =+O32 -> 0 | AD32: =+CONCATENATE(A32,B32,D32) -> 1131ISR PAGO PROVISIONALES | AE32: =+VLOOKUP(AD32,Catálogo!E:F,2,0) -> Impuestos por recuperar | AF32: =+VLOOKUP(AD32,Catálogo!E:G,3,0) -> ISR Retenido
A33: 113 | B33: 1 | C33: 2 | D33: ISR RETENCIONES BANCOS | E33: 7040.35 | F33: 8816.32 | G33: 0 | H33: 15856.67 | J33: =+ROUND(H33/1000,0) -> 16 | K33: =+IFERROR(LEFT(AE33,3),0) -> Imp | L33: =+IFERROR(ABS(K33),"ok") -> ok | M33: =+IF(L33="ok",J33,0) -> 16 | O33: =+M33+N33 -> 16 | R33: 113 | S33: 1 | T33: 2 | U33: ISR RETENCIONES BANCOS | V33: 7040.35 | W33: 8816.32 | X33: 0 | Y33: =+O33 -> 16 | AD33: =+CONCATENATE(A33,B33,D33) -> 1131ISR RETENCIONES BANCOS | AE33: =+VLOOKUP(AD33,Catálogo!E:F,2,0) -> Impuestos por recuperar | AF33: =+VLOOKUP(AD33,Catálogo!E:G,3,0) -> ISR Retenido
A34: 114 | B34: 0 | C34: 0 | D34: IMPUESTOS A FAVOR | E34: 21849234 | F34: 19850154 | G34: -392940.62 | H34: 41306447 | J34: =+ROUND(H34/1000,0) -> 41306 | K34: =+IFERROR(LEFT(AE34,3),0) -> 0 | L34: =+IFERROR(ABS(K34),"ok") -> 0 | M34: =+IF(L34="ok",J34,0) -> 0 | O34: =+M34+N34 -> 0 | R34: 114 | S34: 0 | T34: 0 | U34: IMPUESTOS A FAVOR | V34: 21849234 | W34: 19850154 | X34: -392940.62 | Y34: =+O34 -> 0 | AD34: =+CONCATENATE(A34,B34,D34) -> 1140IMPUESTOS A FAVOR | AE34: =+VLOOKUP(AD34,Catálogo!E:F,2,0) -> #N/A | AF34: =+VLOOKUP(AD34,Catálogo!E:G,3,0) -> 0
A35: 114 | B35: 1 | C35: 0 | D35: IVA SALDO A FAVOR | E35: 21849234 | F35: 19850154 | G35: -392940.62 | H35: 41306447 | J35: =+ROUND(H35/1000,0) -> 41306 | K35: =+IFERROR(LEFT(AE35,3),0) -> 0 | L35: =+IFERROR(ABS(K35),"ok") -> 0 | M35: =+IF(L35="ok",J35,0) -> 0 | O35: =+M35+N35 -> 0 | R35: 114 | S35: 1 | T35: 0 | U35: IVA SALDO A FAVOR | V35: 21849234 | W35: 19850154 | X35: -392940.62 | Y35: =+O35 -> 0 | AD35: =+CONCATENATE(A35,B35,D35) -> 1141IVA SALDO A FAVOR | AE35: =+VLOOKUP(AD35,Catálogo!E:F,2,0) -> #N/A | AF35: =+VLOOKUP(AD35,Catálogo!E:G,3,0) -> 0
A36: 114 | B36: 1 | C36: 1 | D36: IVA SALDO A FAVOR AL 16% | E36: 21849234 | F36: 19850154 | G36: -392940.62 | H36: 41306447 | J36: =+ROUND(H36/1000,0) -> 41306 | K36: =+IFERROR(LEFT(AE36,3),0) -> Inv | L36: =+IFERROR(ABS(K36),"ok") -> ok | M36: =+IF(L36="ok",J36,0) -> 41306 | O36: =+M36+N36 -> 41306 | R36: 114 | S36: 1 | T36: 1 | U36: IVA SALDO A FAVOR AL 16% | V36: 21849234 | W36: 19850154 | X36: -392940.62 | Y36: =+O36 -> 41306 | AD36: =+CONCATENATE(A36,B36,D36) -> 1141IVA SALDO A FAVOR AL 16% | AE36: =+VLOOKUP(AD36,Catálogo!E:F,2,0) -> Inventarios inmobiliarios y costos pagados por anticipado | AF36: =+VLOOKUP(AD36,Catálogo!E:G,3,0) -> Impuesto al Valor Agregado
A37: 115 | B37: 0 | C37: 0 | D37: IMPUESTOS A FAVOR NO CAUSADO | E37: 3744074.6 | F37: 18144824 | G37: -19851507 | H37: 2037391.4 | J37: =+ROUND(H37/1000,0) -> 2037 | K37: =+IFERROR(LEFT(AE37,3),0) -> 0 | L37: =+IFERROR(ABS(K37),"ok") -> 0 | M37: =+IF(L37="ok",J37,0) -> 0 | O37: =+M37+N37 -> 0 | R37: 115 | S37: 0 | T37: 0 | U37: IMPUESTOS A FAVOR NO CAUSADO | V37: 3744074.6 | W37: 18144824 | X37: -19851507 | Y37: =+O37 -> 0 | AD37: =+CONCATENATE(A37,B37,D37) -> 1150IMPUESTOS A FAVOR NO CAUSADO | AE37: =+VLOOKUP(AD37,Catálogo!E:F,2,0) -> #N/A | AF37: =+VLOOKUP(AD37,Catálogo!E:G,3,0) -> 0
A38: 115 | B38: 1 | C38: 0 | D38: IVA ACREDITABLE NO PAGADO | E38: 3744074.6 | F38: 18144824 | G38: -19851507 | H38: 2037391.4 | J38: =+ROUND(H38/1000,0) -> 2037 | K38: =+IFERROR(LEFT(AE38,3),0) -> 0 | L38: =+IFERROR(ABS(K38),"ok") -> 0 | M38: =+IF(L38="ok",J38,0) -> 0 | O38: =+M38+N38 -> 0 | R38: 115 | S38: 1 | T38: 0 | U38: IVA ACREDITABLE NO PAGADO | V38: 3744074.6 | W38: 18144824 | X38: -19851507 | Y38: =+O38 -> 0 | AD38: =+CONCATENATE(A38,B38,D38) -> 1151IVA ACREDITABLE NO PAGADO | AE38: =+VLOOKUP(AD38,Catálogo!E:F,2,0) -> #N/A | AF38: =+VLOOKUP(AD38,Catálogo!E:G,3,0) -> 0
A39: 115 | B39: 1 | C39: 1 | D39: IVA ACREDITABLE NO PAGADO AL 16% | E39: 3744074.6 | F39: 18144824 | G39: -19851507 | H39: 2037391.4 | J39: =+ROUND(H39/1000,0) -> 2037 | K39: =+IFERROR(LEFT(AE39,3),0) -> Deu | L39: =+IFERROR(ABS(K39),"ok") -> ok | M39: =+IF(L39="ok",J39,0) -> 2037 | O39: =+M39+N39 -> 2037 | R39: 115 | S39: 1 | T39: 1 | U39: IVA ACREDITABLE NO PAGADO AL 16% | V39: 3744074.6 | W39: 18144824 | X39: -19851507 | Y39: =+O39 -> 2037 | AD39: =+CONCATENATE(A39,B39,D39) -> 1151IVA ACREDITABLE NO PAGADO AL 16% | AE39: =+VLOOKUP(AD39,Catálogo!E:F,2,0) -> Deudores diversos y otras cuentas por cobrar | AF39: =+VLOOKUP(AD39,Catálogo!E:G,3,0) -> 0
A40: 120 | B40: 0 | C40: 0 | D40: ANTICIPOS CONSTRUCCION | E40: 10998418 | F40: 0 | G40: 0 | H40: 10998418 | J40: =+ROUND(H40/1000,0) -> 10998 | K40: =+IFERROR(LEFT(AE40,3),0) -> 0 | L40: =+IFERROR(ABS(K40),"ok") -> 0 | M40: =+IF(L40="ok",J40,0) -> 0 | O40: =+M40+N40 -> 0 | R40: 120 | S40: 0 | T40: 0 | U40: ANTICIPOS CONSTRUCCION | V40: 10998418 | W40: 0 | X40: 0 | Y40: =+O40 -> 0 | AD40: =+CONCATENATE(A40,B40,D40) -> 1200ANTICIPOS CONSTRUCCION | AE40: =+VLOOKUP(AD40,Catálogo!E:F,2,0) -> #N/A | AF40: =+VLOOKUP(AD40,Catálogo!E:G,3,0) -> 0
A41: 120 | B41: 1 | C41: 0 | D41: ANTICIPOS CONSTRUCCION M.N. | E41: 10998418 | F41: 0 | G41: 0 | H41: 10998418 | J41: =+ROUND(H41/1000,0) -> 10998 | K41: =+IFERROR(LEFT(AE41,3),0) -> Inv | L41: =+IFERROR(ABS(K41),"ok") -> ok | M41: =+IF(L41="ok",J41,0) -> 10998 | O41: =+M41+N41 -> 10998 | R41: 120 | S41: 1 | T41: 0 | U41: ANTICIPOS CONSTRUCCION M.N. | V41: 10998418 | W41: 0 | X41: 0 | Y41: =+O41 -> 10998 | AD41: =+CONCATENATE(A41,B41,D41) -> 1201ANTICIPOS CONSTRUCCION M.N. | AE41: =+VLOOKUP(AD41,Catálogo!E:F,2,0) -> Inventarios inmobiliarios y costos pagados por anticipado | AF41: =+VLOOKUP(AD41,Catálogo!E:G,3,0) -> Otros pagos anticipados (v)
... A77: 125 | B77: 1 | C77: 2 | D77: DEPRECIACIÓN EQP COMPUTO | E77: -81980 | F77: 0 | G77: -53430 | H77: -135410 | J77: =+ROUND(H77/1000,0) -> -135 | K77: =+IFERROR(LEFT(AE77,3),0) -> Mob | L77: =+IFERROR(ABS(K77),"ok") -> ok | M77: =+IF(L77="ok",J77,0) -> -135 | O77: =+M77+N77 -> -135 | R77: 125 | S77: 1 | T77: 2 | U77: DEPRECIACIÓN EQP COMPUTO | V77: -81980 | W77: 0 | X77: -53430 | Y77: =+O77 -> -135 | AD77: =+CONCATENATE(A77,B77,D77) -> 1251DEPRECIACIÓN EQP COMPUTO | AE77: =+VLOOKUP(AD77,Catálogo!E:F,2,0) -> Mobiliario y equipo, neto | AF77: =+VLOOKUP(AD77,Catálogo!E:G,3,0) -> 0
A78: 173 | B78: 0 | C78: 0 | D78: DEPOSITOS EN GARANTIA | E78: 0 | F78: 3074005 | G78: -2957500 | H78: 116505 | J78: =+ROUND(H78/1000,0) -> 117 | K78: =+IFERROR(LEFT(AE78,3),0) -> 0 | L78: =+IFERROR(ABS(K78),"ok") -> 0 | M78: =+IF(L78="ok",J78,0) -> 0 | O78: =+M78+N78 -> 0 | R78: 173 | S78: 0 | T78: 0 | U78: DEPOSITOS EN GARANTIA | V78: 0 | W78: 3074005 | X78: -2957500 | Y78: =+O78 -> 0 | AD78: =+CONCATENATE(A78,B78,D78) -> 1730DEPOSITOS EN GARANTIA | AE78: =+VLOOKUP(AD78,Catálogo!E:F,2,0) -> #N/A | AF78: 0
A79: 173 | B79: 1 | C79: 0 | D79: DEPOSITOS EN GARANTIA M.N. | E79: 0 | F79: 3074005 | G79: -2957500 | H79: 116505 | J79: =+ROUND(H79/1000,0) -> 117 | K79: =+IFERROR(LEFT(AE79,3),0) -> Inv | L79: =+IFERROR(ABS(K79),"ok") -> ok | M79: =+IF(L79="ok",J79,0) -> 117 | O79: =+M79+N79 -> 117 | R79: 173 | S79: 1 | T79: 0 | U79: DEPOSITOS EN GARANTIA M.N. | V79: 0 | W79: 3074005 | X79: -2957500 | Y79: =+O79 -> 117 | AD79: =+CONCATENATE(A79,B79,D79) -> 1731DEPOSITOS EN GARANTIA M.N. | AE79: =+VLOOKUP(AD79,Catálogo!E:F,2,0) -> Inventarios inmobiliarios y costos pagados por anticipado | AF79: =+VLOOKUP(AD79,Catálogo!E:G,3,0) -> Otros pagos anticipados (v)
A80: 201 | B80: 0 | C80: 0 | D80: PROVEEDORES | E80: -18621429 | F80: 3.1238242e+08 | G80: -3.0111823e+08 | H80: -7357238.8 | J80: =+ROUND(H80/1000,0) -> -7357 | K80: =+IFERROR(LEFT(AE80,3),0) -> 0 | L80: =+IFERROR(ABS(K80),"ok") -> 0 | M80: =+IF(L80="ok",J80,0) -> 0 | O80: =+M80+N80 -> 0 | R80: 201 | S80: 0 | T80: 0 | U80: PROVEEDORES | V80: -18621429 | W80: 3.1238242e+08 | X80: -3.0111823e+08 | Y80: =+O80 -> 0 | AD80: =+CONCATENATE(A80,B80,D80) -> 2010PROVEEDORES | AE80: =+VLOOKUP(AD80,Catálogo!E:F,2,0) -> #N/A | AF80: =+VLOOKUP(AD80,Catálogo!E:G,3,0) -> 0
A81: 201 | B81: 1 | C81: 0 | D81: PROVEEDORES M.N. | E81: -18438327 | F81: 3.1029025e+08 | G81: -2.9921328e+08 | H81: -7361354.8 | J81: =+ROUND(H81/1000,0) -> -7361 | K81: =+IFERROR(LEFT(AE81,3),0) -> Pro | L81: =+IFERROR(ABS(K81),"ok") -> ok | M81: =+IF(L81="ok",J81,0) -> -7361 | O81: =+M81+N81 -> -7361 | R81: 201 | S81: 1 | T81: 0 | U81: PROVEEDORES M.N. | V81: -18438327 | W81: 3.1029025e+08 | X81: -2.9921328e+08 | Y81: =+O81 -> -7361 | AD81: =+CONCATENATE(A81,B81,D81) -> 2011PROVEEDORES M.N. | AE81: =+VLOOKUP(AD81,Catálogo!E:F,2,0) -> Proveedores y acreedores diversos | AF81: =+VLOOKUP(AD81,Catálogo!E:G,3,0) -> 0
A82: 201 | B82: 2 | C82: 0 | D82: PROVEEDORES M.E. | E82: -9457.03 | F82: 122319.1 | G82: -112862.07 | H82: 0 | J82: =+ROUND(H82/1000,0) -> 0 | K82: =+IFERROR(LEFT(AE82,3),0) -> Pro | L82: =+IFERROR(ABS(K82),"ok") -> ok | M82: =+IF(L82="ok",J82,0) -> 0 | O82: =+M82+N82 -> 0 | R82: 201 | S82: 2 | T82: 0 | U82: PROVEEDORES M.E. | V82: -9457.03 | W82: 122319.1 | X82: -112862.07 | Y82: =+O82 -> 0 | AD82: =+CONCATENATE(A82,B82,D82) -> 2012PROVEEDORES M.E. | AE82: =+VLOOKUP(AD82,Catálogo!E:F,2,0) -> Proveedores y acreedores diversos | AF82: =+VLOOKUP(AD82,Catálogo!E:G,3,0) -> 0
A83: 201 | B83: 200 | C83: 0 | D83: PROVEEDORES COMPLEMENTARIA | E83: -173644.96 | F83: 1969851.2 | G83: -1792090.3 | H83: 4116 | J83: =+ROUND(H83/1000,0) -> 4 | K83: =+IFERROR(LEFT(AE83,3),0) -> Pro | L83: =+IFERROR(ABS(K83),"ok") -> ok | M83: =+IF(L83="ok",J83,0) -> 4 | O83: =+M83+N83 -> 4 | R83: 201 | S83: 200 | T83: 0 | U83: PROVEEDORES COMPLEMENTARIA | V83: -173644.96 | W83: 1969851.2 | X83: -1792090.3 | Y83: =+O83 -> 4 | AD83: =+CONCATENATE(A83,B83,D83) -> 201200PROVEEDORES COMPLEMENTARIA | AE83: =+VLOOKUP(AD83,Catálogo!E:F,2,0) -> Proveedores y acreedores diversos | AF83: =+VLOOKUP(AD83,Catálogo!E:G,3,0) -> 0
...

Sheet Validación
D8: =SUM(D12:D35) -> 0 | E8: =SUM(E12:E35) -> 0 | F8: =SUM(F12:F31) -> 1 | G8: =SUM(G12:G31) -> 1 | H8: Check
A11: Balance | B11: Clasificación | C11: Plazo | D11: 2024M | E11: 2024 | F11: 2023M | G11: 2023
A12: Efectivo y equivalentes de efectivo | B12: Activo | C12: Corto plazo | D12: =+ROUND(E12,0) -> 42719 | E12: =+SUMIF(BalanzaActual!$AH:$AH,Validación!$A12,BalanzaActual!$Z:$Z) -> 42719 | F12: =+ROUND(G12,0) -> 46651 | G12: =+SUMIF(BalanzaAnterior!$AE:$AE,Validación!$A12,BalanzaAnterior!$Y:$Y) -> 46651
A13: Deudores diversos y otras cuentas por cobrar | B13: Activo | C13: Corto plazo | D13: =+ROUND(E13,0) -> 25042 | E13: =+SUMIF(BalanzaActual!$AH:$AH,Validación!$A13,BalanzaActual!$Z:$Z) -> 25042 | F13: =+ROUND(G13,0) -> 11989 | G13: =+SUMIF(BalanzaAnterior!$AE:$AE,Validación!$A13,BalanzaAnterior!$Y:$Y) -> 11989
A14: Inventarios inmobiliarios y costos pagados por anticipado | B14: Activo | C14: Largo Plazo | D14: =+ROUND(E14,0) -> 1085783 | E14: =+SUMIF(BalanzaActual!$AH:$AH,Validación!$A14,BalanzaActual!$Z:$Z) -> 1085783 | F14: =+ROUND(G14,0) -> 773964 | G14: =+SUMIF(BalanzaAnterior!$AE:$AE,Validación!$A14,BalanzaAnterior!$Y:$Y) -> 773964
A15: Mobiliario y equipo, neto | B15: Activo | C15: Largo Plazo | D15: =+ROUND(E15,0) -> 364 | E15: =+SUMIF(BalanzaActual!$AH:$AH,Validación!$A15,BalanzaActual!$Z:$Z) -> 364 | F15: =+ROUND(G15,0) -> 43 | G15: =+SUMIF(BalanzaAnterior!$AE:$AE,Validación!$A15,BalanzaAnterior!$Y:$Y) -> 43
A16: Impuestos por recuperar | B16: Activo | C16: Largo Plazo | D16: =+ROUND(E16,0) -> 291 | E16: =+SUMIF(BalanzaActual!$AH:$AH,Validación!$A16,BalanzaActual!$Z:$Z) -> 291 | F16: =+ROUND(G16,0) -> 16 | G16: =+SUMIF(BalanzaAnterior!$AE:$AE,Validación!$A16,BalanzaAnterior!$Y:$Y) -> 16
A17: Proveedores y acreedores diversos | B17: Pasivo | C17: Corto plazo | D17: =+ROUND(E17,0) -> -37961 | E17: =+SUMIF(BalanzaActual!$AH:$AH,Validación!$A17,BalanzaActual!$Z:$Z) -> -37961 | F17: =+ROUND(G17,0) -> -13081 | G17: =+SUMIF(BalanzaAnterior!$AE:$AE,Validación!$A17,BalanzaAnterior!$Y:$Y) -> -13081
A18: Acreedores diversos | B18: Pasivo | C18: Corto plazo | D18: =+ROUND(E18,0) -> 0 | E18: =+SUMIF(BalanzaActual!$AH:$AH,Validación!$A18,BalanzaActual!$Z:$Z) -> 0 | F18: =+ROUND(G18,0) -> 0 | G18: =+SUMIF(BalanzaAnterior!$AE:$AE,Validación!$A18,BalanzaAnterior!$Y:$Y) -> 0
A19: Impuestos por pagar | B19: Pasivo | C19: Corto plazo | D19: =+ROUND(E19,0) -> -460 | E19: =+SUMIF(BalanzaActual!$AH:$AH,Validación!$A19,BalanzaActual!$Z:$Z) -> -460 | F19: =+ROUND(G19,0) -> -390 | G19: =+SUMIF(BalanzaAnterior!$AE:$AE,Validación!$A19,BalanzaAnterior!$Y:$Y) -> -390
A20: Depósitos en garantía recibidos | B20: Pasivo | C20: Largo Plazo | D20: =+ROUND(E20,0) -> -407950 | E20: =+SUMIF(BalanzaActual!$AH:$AH,Validación!$A20,BalanzaActual!$Z:$Z) -> -407950 | F20: =+ROUND(G20,0) -> -71045 | G20: =+SUMIF(BalanzaAnterior!$AE:$AE,Validación!$A20,BalanzaAnterior!$Y:$Y) -> -71045
A21: Préstamos a largo plazo | B21: Pasivo | C21: Largo Plazo | D21: =+ROUND(E21,0) -> -330000 | E21: =+SUMIF(BalanzaActual!$AH:$AH,Validación!$A21,BalanzaActual!$Z:$Z) -> -330000 | F21: =+ROUND(G21,0) -> -271000 | G21: =+SUMIF(BalanzaAnterior!$AE:$AE,Validación!$A21,BalanzaAnterior!$Y:$Y) -> -271000
A22: Otras aportaciones del fideicomitente | B22: Pasivo | C22: Largo Plazo | D22: =+ROUND(E22,0) -> -125867 | E22: =+SUMIF(BalanzaActual!$AH:$AH,Validación!$A22,BalanzaActual!$Z:$Z) -> -125867 | F22: =+ROUND(G22,0) -> -196719 | G22: =+SUMIF(BalanzaAnterior!$AE:$AE,Validación!$A22,BalanzaAnterior!$Y:$Y) -> -196719
A23: Aportaciones | B23: Capital | D23: =+ROUND(E23,0) -> -272972 | E23: =+SUMIF(BalanzaActual!$AH:$AH,Validación!$A23,BalanzaActual!$Z:$Z) -> -272972 | F23: =+ROUND(G23,0) -> -272972 | G23: =+SUMIF(BalanzaAnterior!$AE:$AE,Validación!$A23,BalanzaAnterior!$Y:$Y) -> -272972
A24: Resultado del ejercicio | B24: Capital | D24: =+ROUND(E24,0) -> 0 | E24: =+SUMIF(BalanzaActual!$AH:$AH,Validación!$A24,BalanzaActual!$Z:$Z) -> 0 | F24: =+ROUND(G24,0) -> 0 | G24: =+SUMIF(BalanzaAnterior!$AE:$AE,Validación!$A24,BalanzaAnterior!$Y:$Y) -> 0
A25: Resultados acumulados | B25: Capital | D25: =+ROUND(E25,0) -> -7456 | E25: =+SUMIF(BalanzaActual!$AH:$AH,Validación!$A25,BalanzaActual!$Z:$Z) -> -7456 | F25: =+ROUND(G25,0) -> 394 | G25: =+SUMIF(BalanzaAnterior!$AE:$AE,Validación!$A25,BalanzaAnterior!$Y:$Y) -> 394
A26: Ingresos | B26: Resultados | D26: =+ROUND(E26,0) -> 0 | E26: =+SUMIF(BalanzaActual!$AH:$AH,Validación!$A26,BalanzaActual!$Z:$Z) -> 0 | F26: =+ROUND(G26,0) -> 0 | G26: =+SUMIF(BalanzaAnterior!$AE:$AE,Validación!$A26,BalanzaAnterior!$Y:$Y) -> 0
A27: Gastos operativos | B27: Resultados | D27: =+ROUND(E27,0) -> 36492 | E27: =+SUMIF(BalanzaActual!$AH:$AH,Validación!$A27,BalanzaActual!$Z:$Z) -> 36492 | F27: =+ROUND(G27,0) -> 59 | G27: =+SUMIF(BalanzaAnterior!$AE:$AE,Validación!$A27,BalanzaAnterior!$Y:$Y) -> 59
A28: Intereses a cargo | B28: Resultados | D28: =+ROUND(E28,0) -> 21 | E28: =+SUMIF(BalanzaActual!$AH:$AH,Validación!$A28,BalanzaActual!$Z:$Z) -> 21 | F28: =+ROUND(G28,0) -> 11 | G28: =+SUMIF(BalanzaAnterior!$AE:$AE,Validación!$A28,BalanzaAnterior!$Y:$Y) -> 11
A29: Intereses a favor | B29: Resultados | D29: =+ROUND(E29,0) -> -8050 | E29: =+SUMIF(BalanzaActual!$AH:$AH,Validación!$A29,BalanzaActual!$Z:$Z) -> -8050 | F29: =+ROUND(G29,0) -> -2456 | G29: =+SUMIF(BalanzaAnterior!$AE:$AE,Validación!$A29,BalanzaAnterior!$Y:$Y) -> -2456
A30: Otros ingresos | B30: Resultados | D30: =+ROUND(E30,0) -> 0 | E30: =+SUMIF(BalanzaActual!$AH:$AH,Validación!$A30,BalanzaActual!$Z:$Z) -> 0 | F30: =+ROUND(G30,0) -> -5463 | G30: =+SUMIF(BalanzaAnterior!$AE:$AE,Validación!$A30,BalanzaAnterior!$Y:$Y) -> -5463
A31: Fluctuación cambiaria | B31: Resultados | D31: =+ROUND(E31,0) -> 4 | E31: =+SUMIF(BalanzaActual!$AH:$AH,Validación!$A31,BalanzaActual!$Z:$Z) -> 4 | F31: =+ROUND(G31,0) -> 0 | G31: =+SUMIF(BalanzaAnterior!$AE:$AE,Validación!$A31,BalanzaAnterior!$Y:$Y) -> 0
A32: Traspaso a resultados acumulados

Sheet Portada
B3: =+Datos!C4 -> Fideicomiso Irrevocable 4341
B4: =+Datos!C5 -> Fideicomiso FORTMCK 19-12 Lomas Verdes
B6: =+"Estados financieros "&LOWER(Datos!C7)&", e Informe de los auditores independientes del "&Datos!C10 -> Estados financieros por los ejercicios terminados al 31 de diciembre de 2024 y 2023, e Informe de los auditores independientes del 30 de abril de 2025

Sheet Contenido
B6: =+Datos!C4 -> Fideicomiso Irrevocable 4341
B7: =+Datos!C5 -> Fideicomiso FORTMCK 19-12 Lomas Verdes
B9: =+"Informe de los auditores independientes y estados financieros "&LOWER(Datos!C7) -> Informe de los auditores independientes y estados financieros por los ejercicios terminados al 31 de diciembre de 2024 y 2023
B12: Contenido | C12: Página
B16: Informe de los auditores independientes | C16: 1
B17: Estados de posición financiera | C17: 3
B18: Estados de resultados | C18: 4
B19: Estados de cambios en el patrimonio | C19: 5
B20: Estados de flujos de efectivo | C20: 6
B21: Notas a los estados financieros | C21: 7

Sheet Dictamen 1
B5: Al Comité Técnico y Administrador de
B6: =+Datos!C4 -> Fideicomiso Irrevocable 4341
B7: =+Datos!C5 -> Fideicomiso FORTMCK 19-12 Lomas Verdes
B10: =+UPPER("Informe de los Auditores Independientes") -> INFORME DE LOS AUDITORES INDEPENDIENTES
B14: Opinión
B16: =+CONCATENATE(G16,Datos!C4,", ",Datos!C5,,'Dictamen 1'!G18,LOWER(Datos!C14),'Dictamen 1'!G20) -> Hemos auditado los estados financieros adjuntos de Fideicomiso Irrevocable 4341, Fideicomiso FORTMCK 19-12 Lomas Verdes, (el “Fideicomiso”), que comprenden los estados de posición financiera al 31 de diciembre de 2024 y 2023, los estados de resultados, de cambios en el patrimonio y de flujos de efectivo, por los ejercicios terminados en dichas fechas, así como las notas explicativas de los estados financieros, las cuales incluyen un resumen de las principales políticas contables. | G16: Hemos auditado los estados financieros adjuntos de
B18: =+CONCATENATE("En nuestra opinión, los estados financieros adjuntos presentan razonablemente, en todos los aspectos importantes la situación financiera del Fideicomiso ",LOWER(Datos!C14),", así como su desempeño financiero y sus flujos de efectivo correspondientes a los ejercicios terminados en dicha fecha, de conformidad con las Normas de Información Financiera Mexicanas (NIF).") -> En nuestra opinión, los estados financieros adjuntos presentan razonablemente, en todos los aspectos importantes la situación financiera del Fideicomiso al 31 de diciembre de 2024 y 2023, así como su desempeño financiero y sus flujos de efectivo correspondientes a los ejercicios terminados en dicha fecha, de conformidad con las Normas de Información Financiera Mexicanas (NIF). | G18: , (el “Fideicomiso”), que comprenden los estados de posición financiera
